Workbook
Name fc: Main!$C$60
Name fea: IC!$P$3
Name fpo: Main!$G$63
Name fs: Main!$G$13
Name fsr: Main!$G$10*0.001
Name fthp: Main!$G$61
Name fthz: Main!$G$62
Name IC: IC!$A$2:$A$2
Name INTVcc: Main!$C$32
Name Io: Main!$C$14
Name Kref: BodI!$P$3
Name Rds: Main!$C$39
Name Rl: Main!$C$19*1.3
Name Small_Signal_calculation: PS!$B$65
Name Tfall: IC!$U$3
Name Trise: IC!$T$3
Name Vd: Main!$G$30
Name Vgmode: PS!#REF!
Name Vin_L: PS!#REF!
Name Vin_nom: Main!$C$11
Name Vout: Main!$C$13

Sheet Title_and_Schematics
A1: LT3757/LT3758 Boost Converter Power Design Tool
A2: Rev. 0.4
A3: Updated on 5/11/2011
A4: POWER APPLICATION, LINEAR TECHNOLOGY CORP.
A6: Schematic of typical application of LT3757
A9: Linear Technology Power Design Tool License Agreement/Disclaimer Copyright © 2011, Linear Technology Corporation All rights reserved. This spread sheet program is a powerful design tool that significantly eases the tasks of selecting component values, estimating power loss and efficiency and optimizing the compensation loop. This design tool is copyrighted. You are granted a non-exclusive, non-transferable, royalty-free right solely to design supplies with Linear Technology products. Linear Technology Corporation owns the design tool. You may not redistribute, adapt, translate, reverse engineer, decompile, or disassemble the design tool. Upgrades, modifications, or repairs to this design tool will be strictly at the discretion of Linear Technology. Linear Technology application team is trying our best to improve the accuracy of the design equations integrated in this program. However, we can not guarantee operation to be error free. As always, Linear Technology has made the best effort to support our customers. However, due to the external component value variations, it remains the customer’s responsibility to verify the program's calculation results by actually building the circuit and evaluating its performance.

Sheet IC
B1: Power Stage | M1: Controller | T1: Thermal
A2: Chip | B2: Vin min.(V) | C2: Vin max.(V) | D2: Min. switching frequency(kHz) | E2: Max. switching frequency(kHz) | F2: Min. ON time (ns) | G2: Min.OFF time (ns) | H2: Switch Resisor (mΩ) | I2: beta of power switch | J2: Iq (mA) | K2: Ibias(mA) | L2: Max. Duty Cyle (%) | M2: Vref (V) | N2: gm typ (ms) | O2: Ro of EA (kΩ) | P2: First pole (kHz) | Q2: Rs(mOhm) | R2: Ath | S2: slope se (D>0.5) | T2: Trise (nS) | U2: Tfall (nS) | V2: INTVcc (V) | W2: INTVcc off | X2: INTVcc limit | Y2: Thermal resistance
A3: LT3757 | B3: 2.9 | C3: 40 | D3: 100 | E3: 1000 | F3: 220 | G3: 220 | H3: 0 | I3: =1/0.022 -> 45.454545 | J3: 1 | K3: 2.1 | L3: 96 | M3: 1.6 | N3: 0.23 | O3: 3000 | P3: 10000 | Q3: 0 | R3: =1/5.4/1 -> 0.18518519 | S3: =8.5*5.4*PS!B67*2*PS!B5 -> 8660.9134 | T3: 12 | U3: 12 | V3: 7.2 | W3: 7.5 | X3: 17.5 | Y3: 40
A4: LT3758 | B4: 5.5 | C4: 100 | D4: 100 | E4: 1000 | F4: 220 | G4: 220 | H4: 0 | I4: =1/0.022 -> 45.454545 | J4: 1 | K4: 2.1 | L4: 96 | M4: 1.6 | N4: 0.23 | O4: 3000 | P4: 10000 | Q4: 0 | R4: =1/5.4/1 -> 0.18518519 | S4: =8.5*5.4*PS!B67*2*PS!B5 -> 8660.9134 | T4: 12 | U4: 12 | V4: 7.2 | W4: 7.5 | X4: 20 | Y4: 40

Sheet Main
A1: LT3757/3758 Boost Converter Power Design Tool -for customer use with LTC parts only
A2: Chip selection | B2: LT3758
A3: Project Name:
A4: Date:
A6: Part I - Power Stage Design:
A7: Requirement | C7: =IF(OR(C10<C8, C12>C9), "Vin Out of Range!", "") | D7: =IF(C13<MAX(C10, C11, C12), "Vin>Vout!", "") | E7: Switching Frequency | G7: =IF(OR(G10<G8, G10>G9), "fs Out of Range!", "")
A8: IC Minimum input voltage= | C8: =INDEX(IC!B3:B4,PS!B2) -> 5.5 | D8: V | E8: IC Minimum switching frequency= | G8: =INDEX(IC!D3:D4,PS!B2) -> 100 | H8: kHz
A9: IC Maximum input voltage= | C9: =INDEX(IC!C3:C4,PS!B2) -> 100 | D9: V | E9: IC Maximum switching frequency= | G9: =INDEX(IC!E3:E4,PS!B2) -> 1000 | H9: kHz
A10: Minimum input voltage, [Vin_min]= | C10: 10 | D10: V | E10: Switching frequency,[fs]= | G10: 100 | H10: kHz
A11: Nominal input voltage, [Vin_nom]= | C11: 12 | D11: V | E11: Frequency selection resistor= | G11: =PS!B4 -> 140.34631 | H11: kΩ
A12: Maximum input voltage, [Vin_max]= | C12: 14 | D12: V | E12: User enter actual frequency selection resistor= | G12: 140 | H12: kΩ
A13: Output voltage, [Vout]= | C13: 200 | D13: V | E13: Actual nominal switching frequency= | G13: =PS!B72 -> 100.35537 | H13: kHz
A14: Maximum output current, [Io_max]= | C14: 0.5 | D14: A | E14: IC typical minimum ON time = | G14: =INDEX(IC!F3:F4,PS!B2) -> 220 | H14: nsec
A15: Inductor peak-peak ripple current= | C15: 70 | D15: % | E15: IC typical minimum OFF time = | G15: =INDEX(IC!G3:G4,PS!B2) -> 220 | H15: nsec
A16: Boost Inductor | E16: OFF time at Vin_min = | G16: =C10/(PS!B6*G13)*10^6 -> 497.28463 | H16: nsec
A17: Calculated boost inductor | C17: =PS!B12 -> 24.547686 | D17: µH | E17: ON time at Vin_max = | G17: =(1-C12/PS!B6)/G13*10^6 -> 9268.3908 | H17: nsec
A18: manufacture and Part# | B18: Vishay | C18: IHLP5050EZER100M01 | E18: ="Output Filter Capacitor"&IF(G24=0,", please add capacitor!","") -> Output Filter Capacitor
A19: inductor DCR= | C19: 21.4 | D19: mΩ | E19: Maximum output RMS current= | G19: =PS!B27 -> 2.5604289 | H19: A
A20: User enter inductor= | C20: 10 | D20: µH | E20: Output Ceramic Capacitor Manufacturer
A21: Power loss= | C21: =PS!F44 -> 3.2785484 | D21: W | E21: Part #
A22: Peak current at Vin_min, [Ipk]= | C22: =PS!B17 -> 16.490299 | D22: A | E22: Capacitance of each ceramic capacitor= | G22: 4.7 | H22: µF | I22: =PS!B18 -> 1.9749078
A23: Input Capacitor Selection | E23: ESR of each ceramic capacitor= | G23: 100 | H23: mΩ
A24: Nominal input RMS current, [Irms_nom]= | C24: =PS!B20 -> 3.2406155 | D24: A | E24: # of output ceramic capacitors= | G24: 4
A25: Maximum input RMS current, [Irms_max]= | C25: =PS!B22 -> 3.7414222 | D25: A | E25: Estimated Peak to peak output ripple voltage at nominal voltage[Vopp]= | G25: =PS!C33 -> 780.37849 | H25: mV
A26: Input Ceramic Capacitor manufacture | E26: Output ripple voltage percentage = | G26: =G25*0.1/C13 -> 0.39018925 | H26: %
A27: Part # | E27: Output Diode
A28: Capacitance of input ceramic capacitor= | C28: 470 | D28: µF | E28: Output Diode Manufacturer | G28: Diodes
A29: INTVcc | B29: =IF(PS!F9,IF(INTVcc>MIN(C10,17.5),"External INTVcc must be lower than 17.5V and minimum input",""),"") | E29: Part # | G29: MBRS340T3
A30: =IF(AND(M39,INTVcc<Main!N39),"External INTVcc must be high enough to disable internal LDO","") | E30: VF @ full load current = | G30: 0.38 | H30: V
E31: Power Loss in Forward diode= | G31: =PS!F43 -> 0.19 | H31: W
A32: =IF(PS!F9,"User PLS specify the external INTVcc voltage","") | C32: 7.3 | E32: Current Sensing Resistor
A33: Voltage used to calculate the bias loss = | C33: =IF(PS!D9,Vin_nom,IF(PS!E9,Vout, IF(PS!F9,INTVcc))) -> 12 | E33: Suggested max. sensing resistance (30% margin at min input) | G33: =PS!B56 -> 4.2449201 | H33: mΩ
A34: Loss caused by bias current | C34: =PS!F45+PS!F40 -> 0.028613322 | E34: User enter sensing resistor= | G34: 10 | H34: mΩ
A35: MOSFET Selection (Input from Datasheet) | E35: Maximum power dissipation on current sensing resistor= | G35: =PS!F48 -> 0.8523197 | H35: W
A36: MOSFET maximum drain to source stress | C36: =PS!B6 -> 200.38 | D36: V
A37: Manufacturer | C37: Vishay | E37: Gate Drive Resistance
A38: Part# | C38: SI4840BDY | E38: Typical MOSFET gate resistance, [RG]= | G38: 0.85 | H38: Ω
A39: Typical MOSFET on-resistance @ 75C, [RDSon1]= | C39: 10 | D39: mΩ | E39: External turn on gate resistance, [RGon]= | G39: 0 | H39: Ω | M39: =PS!F9 -> FALSE | N39: =PS!C55 -> 7.5 | O39: =PS!E55 -> 10
A40: Specified gate to source voltage for Qg at datasheet= | C40: 10 | D40: V | E40: External turn off gate resistance, [RGoff]= | G40: 0 | H40: Ω
A41: Maximum total gate charge ,[Qg]= | C41: 33 | D41: nC | E41: Total turn on gate resistance = | G41: =G38+G39 -> 0.85 | H41: Ω
...

Sheet Components
A1: Component Tables
A2: Please use this page to store your favourite parts. Data can be copied and pasted to main sheet.
A3: Please contact vendors for detailed data.
A6: Inductor Manufacturer | B6: Sumida | C6: Vishay
A7: Part # | B7: CDRH5D16NP-6R8NC | C7: IHLP5050EZER100M01
A8: Inductance (uH)= | B8: 6.8 | C8: 10
A9: Inductor DCR (mΩ)= | B9: 67.4 | C9: 21.4
A10: Saturation Current (A)= | B10: 1.8 | C10: 16
A11: Temperature risng Current (A)= | B11: 1.7 | C11: 9
A12: Package
A15: Capacitor Manufacturer
A16: Part#
A17: Capacitance (uF)=
A18: ESR (mΩ)=
A19: ESL(nH) =
A20: Package

Sheet PS
A1: Chip name | B1: LT3758(Boost)
B2: =MATCH(Main!$B$2,IC!A3:A4,0) -> 2
A3: fs selection (true for Rt) | B3: TRUE
A4: RT(kOhm)= | B4: =23174*Main!G10^(-1.1089) -> 140.34631
A5: fs(kHz)= | B5: =8618.2*Main!G12^(-0.9011) -> 100.35537
A6: VOF= | B6: =Main!C13+Main!G30 -> 200.38
A7: D_min= | B7: =(B6-Main!C12)/(B6-(Rl+Main!C39)*0.001*Io) -> 0.93022053
A8: D_max= | B8: =(B6-Main!C10)/(B6-(Rl+Main!C39)*0.001*Io) -> 0.95018449
A9: D_nom= | B9: =(B6-Main!C11)/(B6-(Rl+Main!C39)*0.001*Io) -> 0.94020251 | D9: TRUE | E9: FALSE | F9: FALSE
A10: =B7<0.5 -> FALSE | B10: =B8>0.5 -> TRUE
A11: Inductor
A12: L= | B12: =B6*(1-B7)^2*B7/Main!G13/Io/(1*Main!C15)*10^5*0.95 -> 24.547686 | C12: =B6*(1-B8)^2*B8/Main!G13/Io/(1*Main!C15)*10^5*0.95 -> 12.779282
A13: Inductor avg current @ Vin_nom= | B13: =Main!C13*Io/(Main!C11*B37) -> 8.3333333 | C13: =Main!C13*Io/(Main!C11*B53/100) -> 8.8914007 | D13: =Main!C13*Io/(Main!C11*C53/100) -> 8.9465448 | E13: =Main!C13*Io/(Main!C11*D53/100) -> 8.9521486 | F13: =Main!C13*Io/(Main!C11*E53/100) -> 8.9527197
A14: Inductor avg current @ Vin_min= | B14: =Main!C13*Io/(Main!C10*0.85) -> 11.764706 | C14: =IF(C13>=B15,C13-B15,0) -> 3.27849 | D14: =IF(D13>=B15,D13-B15,0) -> 3.3336341 | E14: =IF(E13>=B15,E13-B15,0) -> 3.3392379 | F14: =IF(E13>=B15,E13-B15,0) -> 3.3392379
A15: Inductor ripple (avg to peak) @ Vin_nom= | B15: =B6*(1-B9)*B9/Main!C20/Main!G13*500 -> 5.6129107 | C15: =IF(B13>=B15,B13-B15,0) -> 2.7204226
A16: Delta ripple @ Vin_nom (%)= | B16: =B15*200/B13 -> 134.70986
A17: peak current @ Vin_min= | B17: =B6*(1-B8)*B8/Main!C20/Main!G13*500+B14 -> 16.490299
A18: guaranteed current limit= | B18: =IF(B8<0.5, 2.2, 2.2-(B8-0.5)*(2.5-2.25)/(0.8-0.3)) -> 1.9749078
A19: Input Cap RMS current
A20: Nom RMS= | B20: =B15/SQRT(3) -> 3.2406155
A21: D for Max RMS= | B21: =A10*B10/2+(1-A10)*B8+(1-B10)*B7 -> 0.95018449
A22: Max RMS = | B22: =MAX(B20,C22,D22) -> 3.7414222 | C22: =B6*(1-B7)*B7/Main!C20/Main!G13*1000/2/SQRT(3) -> 3.7414222 | D22: =B6*(1-B8)*B8/Main!C20/Main!G13*1000/2/SQRT(3) -> 2.7283223
A23: Output Cap RMS current
A24: Inductor ripple (avg to peak) @ Vin_min= | B24: =B6*(1-B8)*B8/Main!C20/Main!G13*500 -> 4.7255929
A25: 1-Dmax= | B25: =1-B8 -> 0.049815511
A26: Max RMS (w/o consider efficiency) = | B26: =SQRT(B25*((Io/B25)^2*B8+B24^2/3)) -> 2.2670093
A27: Max RMS (consider efficiency) = | B27: =SQRT(B8*Io^2+B25*(B14^2*B8^2+B15/3)) -> 2.5604289
A28: Output Cap Voltage ripple
A29: equivalent ESR= | B29: =Main!G23/Main!G24/1000 -> 0.025 | C29: modified output C ripple
A30: equivalent cap= | B30: =Main!G22*Main!G24*10^-6 -> 1.88e-05 | C30: =SQRT(B29^2+1/(2*PI()*B30*fs*1000)^2) -> 0.087983645
A31: delta ripple by ESR = | B31: =Main!G23*(Io*(1+1/B25)+B15) -> 1614.9945
A32: delta ripple by cap = | B32: =B9*1000/B5/Main!G24/Main!G22*1000 -> 498.3368
A33: total ripple = | B33: =B31+B32 -> 2113.3313 | C33: =2*SQRT(3)*B27*C30*1000 -> 780.37849
A34: Impedance = | B34: =SQRT((Main!G23)^2+(10^6/(Main!G22*2*PI()*Main!G13))^2) -> 351.93458
B35: =3*B26*B34/Main!G24 -> 598.37922 | C35: from ref
A36: Efficiency Estimation | C36: Another Step | D36: Another Step | E36: Another Step
A37: estimated efficiency = | B37: 1 | C37: =B53 -> 93.723516 | D37: =C53 -> 93.145829 | E37: =D53 -> 93.087522 | F37: =E53 -> 93.081585
A38: switch conduction loss = | B38: =Rds*B13^2*B9*(1+B15^2/3)*0.001*0 -> 0 | C38: =Rds*C13^2*B9*(1+B15^2/3)*0.001*0 -> 0 | D38: =Rds*D13^2*B9*(1+B15^2/3)*0.001*0 -> 0 | E38: =Rds*E13^2*B9*(1+B15^2/3)*0.001*0 -> 0 | F38: =Rds*F13^2*B9*(1+B15^2/3)*0.001*0 -> 0
A39: switch switching loss = | B39: =(Trise+Tfall)*0.5*B6*B13*fs*10^-6*0 -> 0 | C39: =(Trise+Tfall)*0.5*B6*C13*fs*10^-6*0 -> 0 | D39: =(Trise+Tfall)*0.5*B6*D13*fs*10^-6*0 -> 0 | E39: =(Trise+Tfall)*0.5*B6*E13*fs*10^-6*0 -> 0 | F39: =(Trise+Tfall)*0.5*B6*F13*fs*10^-6*0 -> 0
A40: drive loss = | B40: =IF(F9,0.001*Vin_nom, Main!C41/Main!C40*IC!V3*Main!C33*fs/10^6) -> 0.028613322 | C40: =IF(F9,0.001*Vin_nom, Main!C41/Main!C40*IC!V3*Main!C33*fs/10^6) -> 0.028613322 | D40: =IF(F9,0.001*Vin_nom, Main!C41/Main!C40*IC!V3*Main!C33*fs/10^6) -> 0.028613322 | E40: =IF(F9,0.001*Vin_nom, Main!C41/Main!C40*IC!V3*Main!C33*fs/10^6) -> 0.028613322 | F40: =IF(F9,0.001*Vin_nom, Main!C41/Main!C40*IC!V3*Main!C33*fs/10^6) -> 0.028613322
...

Sheet BodI
A1: Index | B1: f(k) | C1: =(LOG(Main!G13)+2)/180 -> 0.022230781 | E1: Ycden | F1: Yreal | G1: Yimag | H1: Vge_mag | I1: Vge_arg | J1: EQ_R | K1: EQ_J | L1: R | M1: J | N1: ith2vo^2 | O1: ith2vo(rad) | Q1: D_mag | R1: D_arg | S1: As^2 | T1: As_arg | U1: Vloop | Y1: ith2vo mag (dB) | Z1: ith2vo(deg)
A2: 100 | B2: =A2/1000 -> 0.1 | C2: 2*PI | D2: =B2*$C$9*1000 -> 0.00029530971 | E2: =B2*1000*$C$18/(1+D2^2) -> 0.011812387 | F2: =D2*E2+$C$24 -> 0.0025034883 | G2: =E2 -> 0.011812387 | H2: =($C$40+($C$34*B2*1000)^2) -> 144.0077 | I2: =ATAN2($C$41,-(B2*1000)) -> -0.0073144792 | J2: =$C$48+$C$38*(B2*1000)/TAN($C$50*(B2*1000)) -> 9.7543397 | K2: =$C$51*B2*1000 -> -0.024185571 | L2: =F2*J2-G2*K2+$C$44 -> 0.067886389 | M2: =J2*G2+K2*F2+($C$55+$C$65)*B2*1000 -> 0.1150419 | N2: =H2/(L2^2+M2^2) -> 8070.733 | O2: =I2-ATAN2(L2,M2) -> -1.0450015 | P2: Kref | Q2: =$P$4+10*LOG((1+($P$6*B2)^2)/(1+($P$8*B2)^2)) -> -23.493182 | R2: =DEGREES(ATAN(B2*$P$6)-ATAN(B2*$P$8)) -> 0 | S2: =((1+($P$24*B2*1000)^2)/((1-$P$28*B2*1000*$P$24*B2*1000)^2+$P$31*(B2*1000)^2))/(1+(B2/fea)^2) -> 0.52563926 | T2: =ATAN(B2*1000*$P$24)-ATAN2(1-$P$24*B2*1000*$P$28*B2*1000,B2*1000*$P$30)-ATAN(B2/fea) -> -0.73691127 | U2: =10*LOG(N2*S2)+Q2+$P$21 -> 68.639753 | V2: =DEGREES(T2+O2)+R2+180 -> 77.903921 | W2: =-U2 -> -68.639753 | Y2: =10*LOG(N2)+20*LOG($C$29) -> 38.149076 | Z2: =DEGREES(O2) -> -59.874173 | AA2: =10*LOG(S2)+Q2+$P$37 -> 30.490677 | AB2: =DEGREES(T2+R2)+180 -> 137.77809
A3: 104.83348 | B3: =A3/1000 -> 0.10483348 | C3: =0.002*PI() -> 0.0062831853 | D3: =B3*$C$9*1000 -> 0.00030958344 | E3: =B3*1000*$C$18/(1+D3^2) -> 0.012383337 | F3: =D3*E3+$C$24 -> 0.0025038337 | G3: =E3 -> 0.012383337 | H3: =($C$40+($C$34*B3*1000)^2) -> 144.00847 | I3: =ATAN2($C$41,-(B3*1000)) -> -0.0076680095 | J3: =$C$48+$C$38*(B3*1000)/TAN($C$50*(B3*1000)) -> 9.7543365 | K3: =$C$51*B3*1000 -> -0.025354576 | L3: =F3*J3-G3*K3+$C$44 -> 0.067918035 | M3: =J3*G3+K3*F3+($C$55+$C$65)*B3*1000 -> 0.12060238 | N3: =H3/(L3^2+M3^2) -> 7516.9656 | O3: =I3-ATAN2(L3,M3) -> -1.0655762 | P3: =Main!C63/(Main!C63+Main!C67) -> 0.06688687 | Q3: =$P$4+10*LOG((1+($P$6*B3)^2)/(1+($P$8*B3)^2)) -> -23.493182 | R3: =DEGREES(ATAN(B3*$P$6)-ATAN(B3*$P$8)) -> 0 | S3: =((1+($P$24*B3*1000)^2)/((1-$P$28*B3*1000*$P$24*B3*1000)^2+$P$31*(B3*1000)^2))/(1+(B3/fea)^2) -> 0.50207474 | T3: =ATAN(B3*1000*$P$24)-ATAN2(1-$P$24*B3*1000*$P$28*B3*1000,B3*1000*$P$30)-ATAN(B3/fea) -> -0.75938373 | U3: =10*LOG(N3*S3)+Q3+$P$21 -> 68.131855 | V3: =DEGREES(T3+O3)+R3+180 -> 75.4375 | W3: =-U3 -> -68.131855 | Y3: =10*LOG(N3)+20*LOG($C$29) -> 37.840372 | Z3: =DEGREES(O3) -> -61.053017 | AA3: =10*LOG(S3)+Q3+$P$37 -> 30.291483 | AB3: =DEGREES(T3+R3)+180 -> 136.49052
A4: 109.90058 | B4: =A4/1000 -> 0.10990058 | C4: Cb*Rb*2*pi | D4: =B4*$C$9*1000 -> 0.0003245471 | E4: =B4*1000*$C$18/(1+D4^2) -> 0.012981882 | F4: =D4*E4+$C$24 -> 0.0025042132 | G4: =E4 -> 0.012981882 | H4: =($C$40+($C$34*B4*1000)^2) -> 144.00931 | I4: =ATAN2($C$41,-(B4*1000)) -> -0.0080386255 | J4: =$C$48+$C$38*(B4*1000)/TAN($C$50*(B4*1000)) -> 9.7543331 | K4: =$C$51*B4*1000 -> -0.026580084 | L4: =F4*J4-G4*K4+$C$44 -> 0.067952813 | M4: =J4*G4+K4*F4+($C$55+$C$65)*B4*1000 -> 0.12643161 | N4: =H4/(L4^2+M4^2) -> 6989.8821 | O4: =I4-ATAN2(L4,M4) -> -1.0856649 | P4: =20*LOG(P3*1) -> -23.493182 | Q4: =$P$4+10*LOG((1+($P$6*B4)^2)/(1+($P$8*B4)^2)) -> -23.493182 | R4: =DEGREES(ATAN(B4*$P$6)-ATAN(B4*$P$8)) -> 0 | S4: =((1+($P$24*B4*1000)^2)/((1-$P$28*B4*1000*$P$24*B4*1000)^2+$P$31*(B4*1000)^2))/(1+(B4/fea)^2) -> 0.47850242 | T4: =ATAN(B4*1000*$P$24)-ATAN2(1-$P$24*B4*1000*$P$28*B4*1000,B4*1000*$P$30)-ATAN(B4/fea) -> -0.78180612 | U4: =10*LOG(N4*S4)+Q4+$P$21 -> 67.607286 | V4: =DEGREES(T4+O4)+R4+180 -> 73.00179 | W4: =-U4 -> -67.607286 | Y4: =10*LOG(N4)+20*LOG($C$29) -> 37.524645 | Z4: =DEGREES(O4) -> -62.204019 | AA4: =10*LOG(S4)+Q4+$P$37 -> 30.082641 | AB4: =DEGREES(T4+R4)+180 -> 135.20581
A5: 115.21261 | B5: =A5/1000 -> 0.11521261 | D5: =B5*$C$9*1000 -> 0.00034023401 | E5: =B5*1000*$C$18/(1+D5^2) -> 0.013609359 | F5: =D5*E5+$C$24 -> 0.0025046304 | G5: =E5 -> 0.013609359 | H5: =($C$40+($C$34*B5*1000)^2) -> 144.01023 | I5: =ATAN2($C$41,-(B5*1000)) -> -0.0084271529 | J5: =$C$48+$C$38*(B5*1000)/TAN($C$50*(B5*1000)) -> 9.7543293 | K5: =$C$51*B5*1000 -> -0.027864827 | L5: =F5*J5-G5*K5+$C$44 -> 0.067991036 | M5: =J5*G5+K5*F5+($C$55+$C$65)*B5*1000 -> 0.13254259 | N5: =H5/(L5^2+M5^2) -> 6489.777 | O5: =I5-ATAN2(L5,M5) -> -1.1052498 | P5: R2*C2 | Q5: =$P$4+10*LOG((1+($P$6*B5)^2)/(1+($P$8*B5)^2)) -> -23.493182 | R5: =DEGREES(ATAN(B5*$P$6)-ATAN(B5*$P$8)) -> 0 | S5: =((1+($P$24*B5*1000)^2)/((1-$P$28*B5*1000*$P$24*B5*1000)^2+$P$31*(B5*1000)^2))/(1+(B5/fea)^2) -> 0.45502702 | T5: =ATAN(B5*1000*$P$24)-ATAN2(1-$P$24*B5*1000*$P$28*B5*1000,B5*1000*$P$30)-ATAN(B5/fea) -> -0.80412338 | U5: =10*LOG(N5*S5)+Q5+$P$21 -> 67.066415 | V5: =DEGREES(T5+O5)+R5+180 -> 70.600973 | W5: =-U5 -> -67.066415 | Y5: =10*LOG(N5)+20*LOG($C$29) -> 37.202244 | Z5: =DEGREES(O5) -> -63.326151 | AA5: =10*LOG(S5)+Q5+$P$37 -> 29.864171 | AB5: =DEGREES(T5+R5)+180 -> 133.92712
A6: 120.78138 | B6: =A6/1000 -> 0.12078138 | C6: Lb*Cb | D6: =B6*$C$9*1000 -> 0.00035667915 | E6: =B6*1000*$C$18/(1+D6^2) -> 0.014267164 | F6: =D6*E6+$C$24 -> 0.0025050888 | G6: =E6 -> 0.014267164 | H6: =($C$40+($C$34*B6*1000)^2) -> 144.01124 | I6: =ATAN2($C$41,-(B6*1000)) -> -0.0088344569 | J6: =$C$48+$C$38*(B6*1000)/TAN($C$50*(B6*1000)) -> 9.7543251 | K6: =$C$51*B6*1000 -> -0.029211667 | L6: =F6*J6-G6*K6+$C$44 -> 0.068033042 | M6: =J6*G6+K6*F6+($C$55+$C$65)*B6*1000 -> 0.13894894 | N6: =H6/(L6^2+M6^2) -> 6016.6879 | O6: =I6-ATAN2(L6,M6) -> -1.1243166 | P6: =Main!C67*Main!C69*PI()*0.000002 -> 0 | Q6: =$P$4+10*LOG((1+($P$6*B6)^2)/(1+($P$8*B6)^2)) -> -23.493182 | R6: =DEGREES(ATAN(B6*$P$6)-ATAN(B6*$P$8)) -> 0 | S6: =((1+($P$24*B6*1000)^2)/((1-$P$28*B6*1000*$P$24*B6*1000)^2+$P$31*(B6*1000)^2))/(1+(B6/fea)^2) -> 0.43175152 | T6: =ATAN(B6*1000*$P$24)-ATAN2(1-$P$24*B6*1000*$P$28*B6*1000,B6*1000*$P$30)-ATAN(B6/fea) -> -0.82628086 | U6: =10*LOG(N6*S6)+Q6+$P$21 -> 66.509659 | V6: =DEGREES(T6+O6)+R6+180 -> 68.238999 | W6: =-U6 -> -66.509659 | Y6: =10*LOG(N6)+20*LOG($C$29) -> 36.873521 | Z6: =DEGREES(O6) -> -64.418595 | AA6: =10*LOG(S6)+Q6+$P$37 -> 29.636138 | AB6: =DEGREES(T6+R6)+180 -> 132.65759
A7: 126.61933 | B7: =A7/1000 -> 0.12661933 | D7: =B7*$C$9*1000 -> 0.00037391917 | E7: =B7*1000*$C$18/(1+D7^2) -> 0.014956765 | F7: =D7*E7+$C$24 -> 0.0025055926 | G7: =E7 -> 0.014956765 | H7: =($C$40+($C$34*B7*1000)^2) -> 144.01235 | I7: =ATAN2($C$41,-(B7*1000)) -> -0.0092614446 | J7: =$C$48+$C$38*(B7*1000)/TAN($C$50*(B7*1000)) -> 9.7543205 | K7: =$C$51*B7*1000 -> -0.030623607 | L7: =F7*J7-G7*K7+$C$44 -> 0.068079208 | M7: =J7*G7+K7*F7+($C$55+$C$65)*B7*1000 -> 0.14566492 | N7: =H7/(L7^2+M7^2) -> 5570.4208 | O7: =I7-ATAN2(L7,M7) -> -1.1428544 | P7: Kref*R1*C12 | Q7: =$P$4+10*LOG((1+($P$6*B7)^2)/(1+($P$8*B7)^2)) -> -23.493182 | R7: =DEGREES(ATAN(B7*$P$6)-ATAN(B7*$P$8)) -> 0 | S7: =((1+($P$24*B7*1000)^2)/((1-$P$28*B7*1000*$P$24*B7*1000)^2+$P$31*(B7*1000)^2))/(1+(B7/fea)^2) -> 0.40877541 | T7: =ATAN(B7*1000*$P$24)-ATAN2(1-$P$24*B7*1000*$P$28*B7*1000,B7*1000*$P$30)-ATAN(B7/fea) -> -0.8482249 | U7: =10*LOG(N7*S7)+Q7+$P$21 -> 65.937473 | V7: =DEGREES(T7+O7)+R7+180 -> 65.919561 | W7: =-U7 -> -65.937473 | Y7: =10*LOG(N7)+20*LOG($C$29) -> 36.538826 | Z7: =DEGREES(O7) -> -65.480732 | AA7: =10*LOG(S7)+Q7+$P$37 -> 29.398647 | AB7: =DEGREES(T7+R7)+180 -> 131.40029
A8: 132.73945 | B8: =A8/1000 -> 0.13273945 | C8: Cc*Rc*2*PI | D8: =B8*$C$9*1000 -> 0.00039199247 | E8: =B8*1000*$C$18/(1+D8^2) -> 0.015679696 | F8: =D8*E8+$C$24 -> 0.0025061463 | G8: =E8 -> 0.015679696 | H8: =($C$40+($C$34*B8*1000)^2) -> 144.01358 | I8: =ATAN2($C$41,-(B8*1000)) -> -0.0097090672 | J8: =$C$48+$C$38*(B8*1000)/TAN($C$50*(B8*1000)) -> 9.7543154 | K8: =$C$51*B8*1000 -> -0.032103793 | L8: =F8*J8-G8*K8+$C$44 -> 0.068129944 | M8: =J8*G8+K8*F8+($C$55+$C$65)*B8*1000 -> 0.1527055 | N8: =H8/(L8^2+M8^2) -> 5150.5785 | O8: =I8-ATAN2(L8,M8) -> -1.1608556 | P8: =P3*Main!C67*(Main!C69+Main!C71)*PI()*0.000002*2 -> 0 | Q8: =$P$4+10*LOG((1+($P$6*B8)^2)/(1+($P$8*B8)^2)) -> -23.493182 | R8: =DEGREES(ATAN(B8*$P$6)-ATAN(B8*$P$8)) -> 0 | S8: =((1+($P$24*B8*1000)^2)/((1-$P$28*B8*1000*$P$24*B8*1000)^2+$P$31*(B8*1000)^2))/(1+(B8/fea)^2) -> 0.38619301 | T8: =ATAN(B8*1000*$P$24)-ATAN2(1-$P$24*B8*1000*$P$28*B8*1000,B8*1000*$P$30)-ATAN(B8/fea) -> -0.86990333 | U8: =10*LOG(N8*S8)+Q8+$P$21 -> 65.35035 | V8: =DEGREES(T8+O8)+R8+180 -> 63.646081 | W8: =-U8 -> -65.35035 | Y8: =10*LOG(N8)+20*LOG($C$29) -> 36.198506 | Z8: =DEGREES(O8) -> -66.512129 | AA8: =10*LOG(S8)+Q8+$P$37 -> 29.151843 | AB8: =DEGREES(T8+R8)+180 -> 130.15821
A9: 139.15538 | B9: =A9/1000 -> 0.13915538 | C9: =Main!G22*C3*Main!G23*10^-6 -> 2.9530971e-06 | D9: =B9*$C$9*1000 -> 0.00041093935 | E9: =B9*1000*$C$18/(1+D9^2) -> 0.016437571 | F9: =D9*E9+$C$24 -> 0.0025067548 | G9: =E9 -> 0.016437571 | H9: =($C$40+($C$34*B9*1000)^2) -> 144.01492 | I9: =ATAN2($C$41,-(B9*1000)) -> -0.010178321 | J9: =$C$48+$C$38*(B9*1000)/TAN($C$50*(B9*1000)) -> 9.7543099 | K9: =$C$51*B9*1000 -> -0.033655523 | L9: =F9*J9-G9*K9+$C$44 -> 0.068185703 | M9: =J9*G9+K9*F9+($C$55+$C$65)*B9*1000 -> 0.16008638 | N9: =H9/(L9^2+M9^2) -> 4756.5879 | O9: =I9-ATAN2(L9,M9) -> -1.178316 | Q9: =$P$4+10*LOG((1+($P$6*B9)^2)/(1+($P$8*B9)^2)) -> -23.493182 | R9: =DEGREES(ATAN(B9*$P$6)-ATAN(B9*$P$8)) -> 0 | S9: =((1+($P$24*B9*1000)^2)/((1-$P$28*B9*1000*$P$24*B9*1000)^2+$P$31*(B9*1000)^2))/(1+(B9/fea)^2) -> 0.36409201 | T9: =ATAN(B9*1000*$P$24)-ATAN2(1-$P$24*B9*1000*$P$28*B9*1000,B9*1000*$P$30)-ATAN(B9/fea) -> -0.89126598 | U9: =10*LOG(N9*S9)+Q9+$P$21 -> 64.748812 | V9: =DEGREES(T9+O9)+R9+180 -> 61.421689 | W9: =-U9 -> -64.748812 | Y9: =10*LOG(N9)+20*LOG($C$29) -> 35.852902 | Z9: =DEGREES(O9) -> -67.512531 | AA9: =10*LOG(S9)+Q9+$P$37 -> 28.895911 | AB9: =DEGREES(T9+R9)+180 -> 128.93422
A10: 145.88143 | B10: =A10/1000 -> 0.14588143 | C10: Lc*Cc | D10: =B10*$C$9*1000 -> 0.00043080202 | E10: =B10*1000*$C$18/(1+D10^2) -> 0.017232077 | F10: =D10*E10+$C$24 -> 0.0025074236 | G10: =E10 -> 0.017232077 | H10: =($C$40+($C$34*B10*1000)^2) -> 144.0164 | I10: =ATAN2($C$41,-(B10*1000)) -> -0.010670252 | J10: =$C$48+$C$38*(B10*1000)/TAN($C$50*(B10*1000)) -> 9.7543038 | K10: =$C$51*B10*1000 -> -0.035282256 | L10: =F10*J10-G10*K10+$C$44 -> 0.068246982 | M10: =J10*G10+K10*F10+($C$55+$C$65)*B10*1000 -> 0.16782399 | N10: =H10/(L10^2+M10^2) -> 4387.7283 | O10: =I10-ATAN2(L10,M10) -> -1.1952337 | P10: G_D, mag | Q10: =$P$4+10*LOG((1+($P$6*B10)^2)/(1+($P$8*B10)^2)) -> -23.493182 | R10: =DEGREES(ATAN(B10*$P$6)-ATAN(B10*$P$8)) -> 0 | S10: =((1+($P$24*B10*1000)^2)/((1-$P$28*B10*1000*$P$24*B10*1000)^2+$P$31*(B10*1000)^2))/(1+(B10/fea)^2) -> 0.34255223 | T10: =ATAN(B10*1000*$P$24)-ATAN2(1-$P$24*B10*1000*$P$28*B10*1000,B10*1000*$P$30)-ATAN(B10/fea) -> -0.91226512 | U10: =10*LOG(N10*S10)+Q10+$P$21 -> 64.133411 | V10: =DEGREES(T10+O10)+R10+180 -> 59.249213 | W10: =-U10 -> -64.133411 | Y10: =10*LOG(N10)+20*LOG($C$29) -> 35.502344 | Z10: =DEGREES(O10) -> -68.481845 | AA10: =10*LOG(S10)+Q10+$P$37 -> 28.631067 | AB10: =DEGREES(T10+R10)+180 -> 127.73106
A11: 152.93257 | B11: =A11/1000 -> 0.15293257 | D11: =B11*$C$9*1000 -> 0.00045162474 | E11: =B11*1000*$C$18/(1+D11^2) -> 0.018064986 | F11: =D11*E11+$C$24 -> 0.0025081586 | G11: =E11 -> 0.018064986 | H11: =($C$40+($C$34*B11*1000)^2) -> 144.01802 | I11: =ATAN2($C$41,-(B11*1000)) -> -0.011185954 | J11: =$C$48+$C$38*(B11*1000)/TAN($C$50*(B11*1000)) -> 9.7542971 | K11: =$C$51*B11*1000 -> -0.036987616 | L11: =F11*J11-G11*K11+$C$44 -> 0.068314329 | M11: =J11*G11+K11*F11+($C$55+$C$65)*B11*1000 -> 0.17593558 | N11: =H11/(L11^2+M11^2) -> 4043.1588 | O11: =I11-ATAN2(L11,M11) -> -1.2116098 | P11: =P3*SQRT((1+(P6*Main!C60)^2)/(1+(Main!C60*P8)^2)) -> 0.06688687 | Q11: =$P$4+10*LOG((1+($P$6*B11)^2)/(1+($P$8*B11)^2)) -> -23.493182 | R11: =DEGREES(ATAN(B11*$P$6)-ATAN(B11*$P$8)) -> 0 | S11: =((1+($P$24*B11*1000)^2)/((1-$P$28*B11*1000*$P$24*B11*1000)^2+$P$31*(B11*1000)^2))/(1+(B11/fea)^2) -> 0.32164463 | T11: =ATAN(B11*1000*$P$24)-ATAN2(1-$P$24*B11*1000*$P$28*B11*1000,B11*1000*$P$30)-ATAN(B11/fea) -> -0.9328558 | U11: =10*LOG(N11*S11)+Q11+$P$21 -> 63.504717 | V11: =DEGREES(T11+O11)+R11+180 -> 57.131171 | W11: =-U11 -> -63.504717 | Y11: =10*LOG(N11)+20*LOG($C$29) -> 35.147154 | Z11: =DEGREES(O11) -> -69.420128 | AA11: =10*LOG(S11)+Q11+$P$37 -> 28.357562 | AB11: =DEGREES(T11+R11)+180 -> 126.5513
A12: 160.32454 | B12: =A12/1000 -> 0.16032454 | C12: 2*PI()*Cb | D12: =B12*$C$9*1000 -> 0.00047345393 | E12: =B12*1000*$C$18/(1+D12^2) -> 0.018938153 | F12: =D12*E12+$C$24 -> 0.0025089663 | G12: =E12 -> 0.018938153 | H12: =($C$40+($C$34*B12*1000)^2) -> 144.0198 | I12: =ATAN2($C$41,-(B12*1000)) -> -0.011726577 | J12: =$C$48+$C$38*(B12*1000)/TAN($C$50*(B12*1000)) -> 9.7542897 | K12: =$C$51*B12*1000 -> -0.038775405 | L12: =F12*J12-G12*K12+$C$44 -> 0.068388343 | M12: =J12*G12+K12*F12+($C$55+$C$65)*B12*1000 -> 0.18443921 | N12: =H12/(L12^2+M12^2) -> 3721.9432 | O12: =I12-ATAN2(L12,M12) -> -1.2274477 | P12: G_D,arg | Q12: =$P$4+10*LOG((1+($P$6*B12)^2)/(1+($P$8*B12)^2)) -> -23.493182 | R12: =DEGREES(ATAN(B12*$P$6)-ATAN(B12*$P$8)) -> 0 | S12: =((1+($P$24*B12*1000)^2)/((1-$P$28*B12*1000*$P$24*B12*1000)^2+$P$31*(B12*1000)^2))/(1+(B12/fea)^2) -> 0.30143061 | T12: =ATAN(B12*1000*$P$24)-ATAN2(1-$P$24*B12*1000*$P$28*B12*1000,B12*1000*$P$30)-ATAN(B12/fea) -> -0.95299618 | U12: =10*LOG(N12*S12)+Q12+$P$21 -> 62.863317 | V12: =DEGREES(T12+O12)+R12+180 -> 55.069769 | W12: =-U12 -> -62.863317 | Y12: =10*LOG(N12)+20*LOG($C$29) -> 34.787644 | Z12: =DEGREES(O12) -> -70.327572 | AA12: =10*LOG(S12)+Q12+$P$37 -> 28.075673 | AB12: =DEGREES(T12+R12)+180 -> 125.39734
A13: 168.07379 | B13: =A13/1000 -> 0.16807379 | D13: =B13*$C$9*1000 -> 0.00049633823 | E13: =B13*1000*$C$18/(1+D13^2) -> 0.019853524 | F13: =D13*E13+$C$24 -> 0.0025098541 | G13: =E13 -> 0.019853524 | H13: =($C$40+($C$34*B13*1000)^2) -> 144.02176 | I13: =ATAN2($C$41,-(B13*1000)) -> -0.012293322 | J13: =$C$48+$C$38*(B13*1000)/TAN($C$50*(B13*1000)) -> 9.7542816 | K13: =$C$51*B13*1000 -> -0.040649606 | L13: =F13*J13-G13*K13+$C$44 -> 0.068469685 | M13: =J13*G13+K13*F13+($C$55+$C$65)*B13*1000 -> 0.19335384 | N13: =H13/(L13^2+M13^2) -> 3423.0743 | O13: =I13-ATAN2(L13,M13) -> -1.2427527 | P13: =ATAN(P6*Main!C60)-ATAN(Main!C60*BodI!P8) -> 0 | Q13: =$P$4+10*LOG((1+($P$6*B13)^2)/(1+($P$8*B13)^2)) -> -23.493182 | R13: =DEGREES(ATAN(B13*$P$6)-ATAN(B13*$P$8)) -> 0 | S13: =((1+($P$24*B13*1000)^2)/((1-$P$28*B13*1000*$P$24*B13*1000)^2+$P$31*(B13*1000)^2))/(1+(B13/fea)^2) -> 0.28196164 | T13: =ATAN(B13*1000*$P$24)-ATAN2(1-$P$24*B13*1000*$P$28*B13*1000,B13*1000*$P$30)-ATAN(B13/fea) -> -0.97264775 | U13: =10*LOG(N13*S13)+Q13+$P$21 -> 62.209809 | V13: =DEGREES(T13+O13)+R13+180 -> 53.066902 | W13: =-U13 -> -62.209809 | Y13: =10*LOG(N13)+20*LOG($C$29) -> 34.42411 | Z13: =DEGREES(O13) -> -71.204487 | AA13: =10*LOG(S13)+Q13+$P$37 -> 27.7857 | AB13: =DEGREES(T13+R13)+180 -> 124.27139
A14: 176.1976 | B14: =A14/1000 -> 0.1761976 | D14: =B14*$C$9*1000 -> 0.00052032863 | E14: =B14*1000*$C$18/(1+D14^2) -> 0.02081314 | F14: =D14*E14+$C$24 -> 0.0025108297 | G14: =E14 -> 0.02081314 | H14: =($C$40+($C$34*B14*1000)^2) -> 144.02392 | I14: =ATAN2($C$41,-(B14*1000)) -> -0.012887453 | J14: =$C$48+$C$38*(B14*1000)/TAN($C$50*(B14*1000)) -> 9.7542728 | K14: =$C$51*B14*1000 -> -0.042614397 | L14: =F14*J14-G14*K14+$C$44 -> 0.068559081 | M14: =J14*G14+K14*F14+($C$55+$C$65)*B14*1000 -> 0.20269933 | N14: =H14/(L14^2+M14^2) -> 3145.4948 | O14: =I14-ATAN2(L14,M14) -> -1.2575323 | Q14: =$P$4+10*LOG((1+($P$6*B14)^2)/(1+($P$8*B14)^2)) -> -23.493182 | R14: =DEGREES(ATAN(B14*$P$6)-ATAN(B14*$P$8)) -> 0 | S14: =((1+($P$24*B14*1000)^2)/((1-$P$28*B14*1000*$P$24*B14*1000)^2+$P$31*(B14*1000)^2))/(1+(B14/fea)^2) -> 0.26327908 | T14: =ATAN(B14*1000*$P$24)-ATAN2(1-$P$24*B14*1000*$P$28*B14*1000,B14*1000*$P$30)-ATAN(B14/fea) -> -0.99177546 | U14: =10*LOG(N14*S14)+Q14+$P$21 -> 61.544799 | V14: =DEGREES(T14+O14)+R14+180 -> 51.124156 | W14: =-U14 -> -61.544799 | Y14: =10*LOG(N14)+20*LOG($C$29) -> 34.056836 | Z14: =DEGREES(O14) -> -72.051295 | AA14: =10*LOG(S14)+Q14+$P$37 -> 27.487963 | AB14: =DEGREES(T14+R14)+180 -> 123.17545
A15: 184.71408 | B15: =A15/1000 -> 0.18471408 | C15: 2*PI()*Cc | D15: =B15*$C$9*1000 -> 0.00054547861 | E15: =B15*1000*$C$18/(1+D15^2) -> 0.021819138 | F15: =D15*E15+$C$24 -> 0.0025119019 | G15: =E15 -> 0.021819138 | H15: =($C$40+($C$34*B15*1000)^2) -> 144.02629 | I15: =ATAN2($C$41,-(B15*1000)) -> -0.013510292 | J15: =$C$48+$C$38*(B15*1000)/TAN($C$50*(B15*1000)) -> 9.754263 | K15: =$C$51*B15*1000 -> -0.044674155 | L15: =F15*J15-G15*K15+$C$44 -> 0.068657327 | M15: =J15*G15+K15*F15+($C$55+$C$65)*B15*1000 -> 0.21249649 | N15: =H15/(L15^2+M15^2) -> 2888.1165 | O15: =I15-ATAN2(L15,M15) -> -1.2717954 | Q15: =$P$4+10*LOG((1+($P$6*B15)^2)/(1+($P$8*B15)^2)) -> -23.493182 | R15: =DEGREES(ATAN(B15*$P$6)-ATAN(B15*$P$8)) -> 0 | S15: =((1+($P$24*B15*1000)^2)/((1-$P$28*B15*1000*$P$24*B15*1000)^2+$P$31*(B15*1000)^2))/(1+(B15/fea)^2) -> 0.24541431 | T15: =ATAN(B15*1000*$P$24)-ATAN2(1-$P$24*B15*1000*$P$28*B15*1000,B15*1000*$P$30)-ATAN(B15/fea) -> -1.0103479 | U15: =10*LOG(N15*S15)+Q15+$P$21 -> 60.868892 | V15: =DEGREES(T15+O15)+R15+180 -> 49.242823 | W15: =-U15 -> -60.868892 | Y15: =10*LOG(N15)+20*LOG($C$29) -> 33.686093 | Z15: =DEGREES(O15) -> -72.868509 | AA15: =10*LOG(S15)+Q15+$P$37 -> 27.182798 | AB15: =DEGREES(T15+R15)+180 -> 122.11133
A16: 193.6422 | B16: =A16/1000 -> 0.1936422 | C16: =C3*Main!G22*10^-3 -> 2.9530971e-05 | D16: =B16*$C$9*1000 -> 0.00057184421 | E16: =B16*1000*$C$18/(1+D16^2) -> 0.022873761 | F16: =D16*E16+$C$24 -> 0.0025130802 | G16: =E16 -> 0.022873761 | H16: =($C$40+($C$34*B16*1000)^2) -> 144.02889 | I16: =ATAN2($C$41,-(B16*1000)) -> -0.014163224 | J16: =$C$48+$C$38*(B16*1000)/TAN($C$50*(B16*1000)) -> 9.7542522 | K16: =$C$51*B16*1000 -> -0.046833471 | L16: =F16*J16-G16*K16+$C$44 -> 0.0687653 | M16: =J16*G16+K16*F16+($C$55+$C$65)*B16*1000 -> 0.22276716 | N16: =H16/(L16^2+M16^2) -> 2649.8368 | O16: =I16-ATAN2(L16,M16) -> -1.2855523 | P16: =SQRT(LOOKUP(Main!C60,B2:B200,N2:N200))*C29 -> 0.83608103 | Q16: =$P$4+10*LOG((1+($P$6*B16)^2)/(1+($P$8*B16)^2)) -> -23.493182 | R16: =DEGREES(ATAN(B16*$P$6)-ATAN(B16*$P$8)) -> 0 | S16: =((1+($P$24*B16*1000)^2)/((1-$P$28*B16*1000*$P$24*B16*1000)^2+$P$31*(B16*1000)^2))/(1+(B16/fea)^2) -> 0.2283891 | T16: =ATAN(B16*1000*$P$24)-ATAN2(1-$P$24*B16*1000*$P$28*B16*1000,B16*1000*$P$30)-ATAN(B16/fea) -> -1.0283371 | U16: =10*LOG(N16*S16)+Q16+$P$21 -> 60.182691 | V16: =DEGREES(T16+O16)+R16+180 -> 47.423904 | W16: =-U16 -> -60.182691 | Y16: =10*LOG(N16)+20*LOG($C$29) -> 33.312138 | Z16: =DEGREES(O16) -> -73.656722 | AA16: =10*LOG(S16)+Q16+$P$37 -> 26.870553 | AB16: =DEGREES(T16+R16)+180 -> 121.08063
A17: 203.00185 | B17: =A17/1000 -> 0.20300185 | C17: Cc*nc*2*pi() | D17: =B17*$C$9*1000 -> 0.00059948418 | E17: =B17*1000*$C$18/(1+D17^2) -> 0.023979359 | F17: =D17*E17+$C$24 -> 0.0025143752 | G17: =E17 -> 0.023979359 | H17: =($C$40+($C$34*B17*1000)^2) -> 144.03175 | I17: =ATAN2($C$41,-(B17*1000)) -> -0.014847702 | J17: =$C$48+$C$38*(B17*1000)/TAN($C$50*(B17*1000)) -> 9.7542404 | K17: =$C$51*B17*1000 -> -0.049097157 | L17: =F17*J17-G17*K17+$C$44 -> 0.068883963 | M17: =J17*G17+K17*F17+($C$55+$C$65)*B17*1000 -> 0.23353421 | N17: =H17/(L17^2+M17^2) -> 2429.5532 | O17: =I17-ATAN2(L17,M17) -> -1.2988147 | P17: =LOOKUP(Main!C60,B2:B200,O2:O200) -> -1.9615552 | Q17: =$P$4+10*LOG((1+($P$6*B17)^2)/(1+($P$8*B17)^2)) -> -23.493182 | R17: =DEGREES(ATAN(B17*$P$6)-ATAN(B17*$P$8)) -> 0 | S17: =((1+($P$24*B17*1000)^2)/((1-$P$28*B17*1000*$P$24*B17*1000)^2+$P$31*(B17*1000)^2))/(1+(B17/fea)^2) -> 0.21221607 | T17: =ATAN(B17*1000*$P$24)-ATAN2(1-$P$24*B17*1000*$P$28*B17*1000,B17*1000*$P$30)-ATAN(B17/fea) -> -1.0457187 | U17: =10*LOG(N17*S17)+Q17+$P$21 -> 59.486792 | V17: =DEGREES(T17+O17)+R17+180 -> 45.668132 | W17: =-U17 -> -59.486792 | Y17: =10*LOG(N17)+20*LOG($C$29) -> 32.93521 | Z17: =DEGREES(O17) -> -74.416599 | AA17: =10*LOG(S17)+Q17+$P$37 -> 26.551582 | AB17: =DEGREES(T17+R17)+180 -> 120.08473
A18: 212.8139 | B18: =A18/1000 -> 0.2128139 | C18: =C16*Main!G24 -> 0.00011812388 | D18: =B18*$C$9*1000 -> 0.00062846012 | E18: =B18*1000*$C$18/(1+D18^2) -> 0.025138395 | F18: =D18*E18+$C$24 -> 0.0025157985 | G18: =E18 -> 0.025138395 | H18: =($C$40+($C$34*B18*1000)^2) -> 144.03489 | I18: =ATAN2($C$41,-(B18*1000)) -> -0.015565249 | J18: =$C$48+$C$38*(B18*1000)/TAN($C$50*(B18*1000)) -> 9.7542275 | K18: =$C$51*B18*1000 -> -0.051470258 | L18: =F18*J18-G18*K18+$C$44 -> 0.069014374 | M18: =J18*G18+K18*F18+($C$55+$C$65)*B18*1000 -> 0.24482163 | N18: =H18/(L18^2+M18^2) -> 2226.1751 | O18: =I18-ATAN2(L18,M18) -> -1.3115951 | Q18: =$P$4+10*LOG((1+($P$6*B18)^2)/(1+($P$8*B18)^2)) -> -23.493182 | R18: =DEGREES(ATAN(B18*$P$6)-ATAN(B18*$P$8)) -> 0 | S18: =((1+($P$24*B18*1000)^2)/((1-$P$28*B18*1000*$P$24*B18*1000)^2+$P$31*(B18*1000)^2))/(1+(B18/fea)^2) -> 0.19689946 | T18: =ATAN(B18*1000*$P$24)-ATAN2(1-$P$24*B18*1000*$P$28*B18*1000,B18*1000*$P$30)-ATAN(B18/fea) -> -1.0624719 | U18: =10*LOG(N18*S18)+Q18+$P$21 -> 58.781784 | V18: =DEGREES(T18+O18)+R18+180 -> 43.975983 | W18: =-U18 -> -58.781784 | Y18: =10*LOG(N18)+20*LOG($C$29) -> 32.55554 | Z18: =DEGREES(O18) -> -75.148861 | AA18: =10*LOG(S18)+Q18+$P$37 -> 26.226245 | AB18: =DEGREES(T18+R18)+180 -> 119.12484
A19: 223.10022 | B19: =A19/1000 -> 0.22310022 | C19: nb+Yo*Rb | D19: =B19*$C$9*1000 -> 0.00065883661 | E19: =B19*1000*$C$18/(1+D19^2) -> 0.026353453 | F19: =D19*E19+$C$24 -> 0.0025173626 | G19: =E19 -> 0.026353453 | H19: =($C$40+($C$34*B19*1000)^2) -> 144.03835 | I19: =ATAN2($C$41,-(B19*1000)) -> -0.016317462 | J19: =$C$48+$C$38*(B19*1000)/TAN($C$50*(B19*1000)) -> 9.7542132 | K19: =$C$51*B19*1000 -> -0.053958062 | L19: =F19*J19-G19*K19+$C$44 -> 0.069157697 | M19: =J19*G19+K19*F19+($C$55+$C$65)*B19*1000 -> 0.25665456 | N19: =H19/(L19^2+M19^2) -> 2038.6338 | O19: =I19-ATAN2(L19,M19) -> -1.3239069 | P19: Fm*Ath*gm*Roth | Q19: =$P$4+10*LOG((1+($P$6*B19)^2)/(1+($P$8*B19)^2)) -> -23.493182 | R19: =DEGREES(ATAN(B19*$P$6)-ATAN(B19*$P$8)) -> 0 | S19: =((1+($P$24*B19*1000)^2)/((1-$P$28*B19*1000*$P$24*B19*1000)^2+$P$31*(B19*1000)^2))/(1+(B19/fea)^2) -> 0.18243582 | T19: =ATAN(B19*1000*$P$24)-ATAN2(1-$P$24*B19*1000*$P$28*B19*1000,B19*1000*$P$30)-ATAN(B19/fea) -> -1.078579 | U19: =10*LOG(N19*S19)+Q19+$P$21 -> 58.068239 | V19: =DEGREES(T19+O19)+R19+180 -> 42.347696 | W19: =-U19 -> -58.068239 | Y19: =10*LOG(N19)+20*LOG($C$29) -> 32.173339 | Z19: =DEGREES(O19) -> -75.85428 | AA19: =10*LOG(S19)+Q19+$P$37 -> 25.8949 | AB19: =DEGREES(T19+R19)+180 -> 118.20198
A20: 233.88372 | B20: =A20/1000 -> 0.23388372 | D20: =B20*$C$9*1000 -> 0.00069068135 | E20: =B20*1000*$C$18/(1+D20^2) -> 0.027627241 | F20: =D20*E20+$C$24 -> 0.0025190816 | G20: =E20 -> 0.027627241 | H20: =($C$40+($C$34*B20*1000)^2) -> 144.04214 | I20: =ATAN2($C$41,-(B20*1000)) -> -0.017106013 | J20: =$C$48+$C$38*(B20*1000)/TAN($C$50*(B20*1000)) -> 9.7541975 | K20: =$C$51*B20*1000 -> -0.056566114 | L20: =F20*J20-G20*K20+$C$44 -> 0.069315209 | M20: =J20*G20+K20*F20+($C$55+$C$65)*B20*1000 -> 0.26905936 | N20: =H20/(L20^2+M20^2) -> 1865.8904 | O20: =I20-ATAN2(L20,M20) -> -1.3357644 | P20: =20*LOG(C29*PS!B76) -> -73.685497 | Q20: =$P$4+10*LOG((1+($P$6*B20)^2)/(1+($P$8*B20)^2)) -> -23.493182 | R20: =DEGREES(ATAN(B20*$P$6)-ATAN(B20*$P$8)) -> 0 | S20: =((1+($P$24*B20*1000)^2)/((1-$P$28*B20*1000*$P$24*B20*1000)^2+$P$31*(B20*1000)^2))/(1+(B20/fea)^2) -> 0.16881493 | T20: =ATAN(B20*1000*$P$24)-ATAN2(1-$P$24*B20*1000*$P$28*B20*1000,B20*1000*$P$30)-ATAN(B20/fea) -> -1.0940255 | U20: =10*LOG(N20*S20)+Q20+$P$21 -> 57.346716 | V20: =DEGREES(T20+O20)+R20+180 -> 40.783295 | W20: =-U20 -> -57.346716 | Y20: =10*LOG(N20)+20*LOG($C$29) -> 31.788808 | Z20: =DEGREES(O20) -> -76.533662 | AA20: =10*LOG(S20)+Q20+$P$37 -> 25.557908 | AB20: =DEGREES(T20+R20)+180 -> 117.31696
A21: 245.18845 | B21: =A21/1000 -> 0.24518845 | C21: nc | D21: =B21*$C$9*1000 -> 0.00072406529 | E21: =B21*1000*$C$18/(1+D21^2) -> 0.028962596 | F21: =D21*E21+$C$24 -> 0.0025209708 | G21: =E21 -> 0.028962596 | H21: =($C$40+($C$34*B21*1000)^2) -> 144.04632 | I21: =ATAN2($C$41,-(B21*1000)) -> -0.017932655 | J21: =$C$48+$C$38*(B21*1000)/TAN($C$50*(B21*1000)) -> 9.7541803 | K21: =$C$51*B21*1000 -> -0.059300226 | L21: =F21*J21-G21*K21+$C$44 -> 0.069488316 | M21: =J21*G21+K21*F21+($C$55+$C$65)*B21*1000 -> 0.28206367 | N21: =H21/(L21^2+M21^2) -> 1706.9417 | O21: =I21-ATAN2(L21,M21) -> -1.3471821 | P21: =P20+20*LOG(PS!B81*1000) -> 55.856928 | Q21: =$P$4+10*LOG((1+($P$6*B21)^2)/(1+($P$8*B21)^2)) -> -23.493182 | R21: =DEGREES(ATAN(B21*$P$6)-ATAN(B21*$P$8)) -> 0 | S21: =((1+($P$24*B21*1000)^2)/((1-$P$28*B21*1000*$P$24*B21*1000)^2+$P$31*(B21*1000)^2))/(1+(B21/fea)^2) -> 0.15602067 | T21: =ATAN(B21*1000*$P$24)-ATAN2(1-$P$24*B21*1000*$P$28*B21*1000,B21*1000*$P$30)-ATAN(B21/fea) -> -1.1087997 | U21: =10*LOG(N21*S21)+Q21+$P$21 -> 56.617754 | V21: =DEGREES(T21+O21)+R21+180 -> 39.282607 | W21: =-U21 -> -56.617754 | Y21: =10*LOG(N21)+20*LOG($C$29) -> 31.402133 | Z21: =DEGREES(O21) -> -77.187848 | AA21: =10*LOG(S21)+Q21+$P$37 -> 25.215621 | AB21: =DEGREES(T21+R21)+180 -> 116.47046
A22: 257.03958 | B22: =A22/1000 -> 0.25703958 | C22: =Main!G24 -> 4 | D22: =B22*$C$9*1000 -> 0.00075906283 | E22: =B22*1000*$C$18/(1+D22^2) -> 0.030362496 | F22: =D22*E22+$C$24 -> 0.002523047 | G22: =E22 -> 0.030362496 | H22: =($C$40+($C$34*B22*1000)^2) -> 144.0509 | I22: =ATAN2($C$41,-(B22*1000)) -> -0.018799227 | J22: =$C$48+$C$38*(B22*1000)/TAN($C$50*(B22*1000)) -> 9.7541614 | K22: =$C$51*B22*1000 -> -0.06216649 | L22: =F22*J22-G22*K22+$C$44 -> 0.069678562 | M22: =J22*G22+K22*F22+($C$55+$C$65)*B22*1000 -> 0.29569644 | N22: =H22/(L22^2+M22^2) -> 1560.8255 | O22: =I22-ATAN2(L22,M22) -> -1.3581751 | Q22: =$P$4+10*LOG((1+($P$6*B22)^2)/(1+($P$8*B22)^2)) -> -23.493182 | R22: =DEGREES(ATAN(B22*$P$6)-ATAN(B22*$P$8)) -> 0 | S22: =((1+($P$24*B22*1000)^2)/((1-$P$28*B22*1000*$P$24*B22*1000)^2+$P$31*(B22*1000)^2))/(1+(B22/fea)^2) -> 0.14403188 | T22: =ATAN(B22*1000*$P$24)-ATAN2(1-$P$24*B22*1000*$P$28*B22*1000,B22*1000*$P$30)-ATAN(B22/fea) -> -1.1228928 | U22: =10*LOG(N22*S22)+Q22+$P$21 -> 55.881876 | V22: =DEGREES(T22+O22)+R22+180 -> 37.845283 | W22: =-U22 -> -55.881876 | Y22: =10*LOG(N22)+20*LOG($C$29) -> 31.01349 | Z22: =DEGREES(O22) -> -77.8177 | AA22: =10*LOG(S22)+Q22+$P$37 -> 24.868386 | AB22: =DEGREES(T22+R22)+180 -> 115.66298
A23: 269.46353 | B23: =A23/1000 -> 0.26946353 | C23: Yo | D23: =B23*$C$9*1000 -> 0.00079575198 | E23: =B23*1000*$C$18/(1+D23^2) -> 0.031830059 | F23: =D23*E23+$C$24 -> 0.0025253288 | G23: =E23 -> 0.031830059 | H23: =($C$40+($C$34*B23*1000)^2) -> 144.05594 | I23: =ATAN2($C$41,-(B23*1000)) -> -0.019707654 | J23: =$C$48+$C$38*(B23*1000)/TAN($C$50*(B23*1000)) -> 9.7541406 | K23: =$C$51*B23*1000 -> -0.065171294 | L23: =F23*J23-G23*K23+$C$44 -> 0.069887643 | M23: =J23*G23+K23*F23+($C$55+$C$65)*B23*1000 -> 0.30998804 | N23: =H23/(L23^2+M23^2) -> 1426.6232 | O23: =I23-ATAN2(L23,M23) -> -1.3687587 | P23: RthCth | Q23: =$P$4+10*LOG((1+($P$6*B23)^2)/(1+($P$8*B23)^2)) -> -23.493182 | R23: =DEGREES(ATAN(B23*$P$6)-ATAN(B23*$P$8)) -> 0 | S23: =((1+($P$24*B23*1000)^2)/((1-$P$28*B23*1000*$P$24*B23*1000)^2+$P$31*(B23*1000)^2))/(1+(B23/fea)^2) -> 0.13282329 | T23: =ATAN(B23*1000*$P$24)-ATAN2(1-$P$24*B23*1000*$P$28*B23*1000,B23*1000*$P$30)-ATAN(B23/fea) -> -1.1362981 | U23: =10*LOG(N23*S23)+Q23+$P$21 -> 55.139581 | V23: =DEGREES(T23+O23)+R23+180 -> 36.470819 | W23: =-U23 -> -55.139581 | Y23: =10*LOG(N23)+20*LOG($C$29) -> 30.623039 | Z23: =DEGREES(O23) -> -78.424096 | AA23: =10*LOG(S23)+Q23+$P$37 -> 24.516542 | AB23: =DEGREES(T23+R23)+180 -> 114.89492
A24: 282.488 | B24: =A24/1000 -> 0.282488 | C24: =(1-PS!B73)*Main!G58/Main!C13 -> 0.0025 | D24: =B24*$C$9*1000 -> 0.00083421448 | E24: =B24*1000*$C$18/(1+D24^2) -> 0.033368556 | F24: =D24*E24+$C$24 -> 0.0025278365 | G24: =E24 -> 0.033368556 | H24: =($C$40+($C$34*B24*1000)^2) -> 144.06148 | I24: =ATAN2($C$41,-(B24*1000)) -> -0.020659954 | J24: =$C$48+$C$38*(B24*1000)/TAN($C$50*(B24*1000)) -> 9.7541177 | K24: =$C$51*B24*1000 -> -0.068321335 | L24: =F24*J24-G24*K24+$C$44 -> 0.070117424 | M24: =J24*G24+K24*F24+($C$55+$C$65)*B24*1000 -> 0.32497029 | N24: =H24/(L24^2+M24^2) -> 1303.4626 | O24: =I24-ATAN2(L24,M24) -> -1.3789484 | P24: =Main!G65*2*Main!G67*PI()*10^-9 -> 0.00024215396 | Q24: =$P$4+10*LOG((1+($P$6*B24)^2)/(1+($P$8*B24)^2)) -> -23.493182 | R24: =DEGREES(ATAN(B24*$P$6)-ATAN(B24*$P$8)) -> 0 | S24: =((1+($P$24*B24*1000)^2)/((1-$P$28*B24*1000*$P$24*B24*1000)^2+$P$31*(B24*1000)^2))/(1+(B24/fea)^2) -> 0.1223663 | T24: =ATAN(B24*1000*$P$24)-ATAN2(1-$P$24*B24*1000*$P$28*B24*1000,B24*1000*$P$30)-ATAN(B24/fea) -> -1.1490113 | U24: =10*LOG(N24*S24)+Q24+$P$21 -> 54.39135 | V24: =DEGREES(T24+O24)+R24+180 -> 35.15858 | W24: =-U24 -> -54.39135 | Y24: =10*LOG(N24)+20*LOG($C$29) -> 30.230932 | Z24: =DEGREES(O24) -> -79.007925 | AA24: =10*LOG(S24)+Q24+$P$37 -> 24.160418 | AB24: =DEGREES(T24+R24)+180 -> 114.1665
A25: 296.142 | B25: =A25/1000 -> 0.296142 | C25: Imode? | D25: =B25*$C$9*1000 -> 0.00087453607 | E25: =B25*1000*$C$18/(1+D25^2) -> 0.034981416 | F25: =D25*E25+$C$24 -> 0.0025305925 | G25: =E25 -> 0.034981416 | H25: =($C$40+($C$34*B25*1000)^2) -> 144.06757 | I25: =ATAN2($C$41,-(B25*1000)) -> -0.021658244 | J25: =$C$48+$C$38*(B25*1000)/TAN($C$50*(B25*1000)) -> 9.7540926 | K25: =$C$51*B25*1000 -> -0.071623633 | L25: =F25*J25-G25*K25+$C$44 -> 0.070369954 | M25: =J25*G25+K25*F25+($C$55+$C$65)*B25*1000 -> 0.34067656 | N25: =H25/(L25^2+M25^2) -> 1190.5186 | O25: =I25-ATAN2(L25,M25) -> -1.3887599 | P25: Roth*Cth | Q25: =$P$4+10*LOG((1+($P$6*B25)^2)/(1+($P$8*B25)^2)) -> -23.493182 | R25: =DEGREES(ATAN(B25*$P$6)-ATAN(B25*$P$8)) -> 0 | S25: =((1+($P$24*B25*1000)^2)/((1-$P$28*B25*1000*$P$24*B25*1000)^2+$P$31*(B25*1000)^2))/(1+(B25/fea)^2) -> 0.11262978 | T25: =ATAN(B25*1000*$P$24)-ATAN2(1-$P$24*B25*1000*$P$28*B25*1000,B25*1000*$P$30)-ATAN(B25/fea) -> -1.1610298 | U25: =10*LOG(N25*S25)+Q25+$P$21 -> 53.63764 | V25: =DEGREES(T25+O25)+R25+180 -> 33.907813 | W25: =-U25 -> -53.63764 | Y25: =10*LOG(N25)+20*LOG($C$29) -> 29.837308 | Z25: =DEGREES(O25) -> -79.570081 | AA25: =10*LOG(S25)+Q25+$P$37 -> 23.800332 | AB25: =DEGREES(T25+R25)+180 -> 113.47789
A26: 310.45596 | B26: =A26/1000 -> 0.31045596 | D26: =B26*$C$9*1000 -> 0.00091680659 | E26: =B26*1000*$C$18/(1+D26^2) -> 0.036672233 | F26: =D26*E26+$C$24 -> 0.0025336213 | G26: =E26 -> 0.036672233 | H26: =($C$40+($C$34*B26*1000)^2) -> 144.07426 | I26: =ATAN2($C$41,-(B26*1000)) -> -0.022704739 | J26: =$C$48+$C$38*(B26*1000)/TAN($C$50*(B26*1000)) -> 9.754065 | K26: =$C$51*B26*1000 -> -0.075085546 | L26: =F26*J26-G26*K26+$C$44 -> 0.070647486 | M26: =J26*G26+K26*F26+($C$55+$C$65)*B26*1000 -> 0.35714183 | N26: =H26/(L26^2+M26^2) -> 1087.0137 | O26: =I26-ATAN2(L26,M26) -> -1.3982088 | P26: =PS!B81*2*Main!G65*PI()*10^-9 -> 0.0088592913 | Q26: =$P$4+10*LOG((1+($P$6*B26)^2)/(1+($P$8*B26)^2)) -> -23.493182 | R26: =DEGREES(ATAN(B26*$P$6)-ATAN(B26*$P$8)) -> 0 | S26: =((1+($P$24*B26*1000)^2)/((1-$P$28*B26*1000*$P$24*B26*1000)^2+$P$31*(B26*1000)^2))/(1+(B26/fea)^2) -> 0.10358075 | T26: =ATAN(B26*1000*$P$24)-ATAN2(1-$P$24*B26*1000*$P$28*B26*1000,B26*1000*$P$30)-ATAN(B26/fea) -> -1.1723528 | U26: =10*LOG(N26*S26)+Q26+$P$21 -> 52.878886 | V26: =DEGREES(T26+O26)+R26+180 -> 32.717673 | W26: =-U26 -> -52.878886 | Y26: =10*LOG(N26)+20*LOG($C$29) -> 29.442296 | Z26: =DEGREES(O26) -> -80.111461 | AA26: =10*LOG(S26)+Q26+$P$37 -> 23.43659 | AB26: =DEGREES(T26+R26)+180 -> 112.82913
A27: 325.46178 | B27: =A27/1000 -> 0.32546178 | C27: =INDEX(IC!R3:R4,PS!B2) -> 0.18518519 | D27: =B27*$C$9*1000 -> 0.00096112025 | E27: =B27*1000*$C$18/(1+D27^2) -> 0.038444774 | F27: =D27*E27+$C$24 -> 0.0025369501 | G27: =E27 -> 0.038444774 | H27: =($C$40+($C$34*B27*1000)^2) -> 144.08161 | I27: =ATAN2($C$41,-(B27*1000)) -> -0.023801763 | J27: =$C$48+$C$38*(B27*1000)/TAN($C$50*(B27*1000)) -> 9.7540347 | K27: =$C$51*B27*1000 -> -0.078714791 | L27: =F27*J27-G27*K27+$C$44 -> 0.070952495 | M27: =J27*G27+K27*F27+($C$55+$C$65)*B27*1000 -> 0.37440274 | N27: =H27/(L27^2+M27^2) -> 992.21784 | O27: =I27-ATAN2(L27,M27) -> -1.4073106 | P27: Roth*Cthp | Q27: =$P$4+10*LOG((1+($P$6*B27)^2)/(1+($P$8*B27)^2)) -> -23.493182 | R27: =DEGREES(ATAN(B27*$P$6)-ATAN(B27*$P$8)) -> 0 | S27: =((1+($P$24*B27*1000)^2)/((1-$P$28*B27*1000*$P$24*B27*1000)^2+$P$31*(B27*1000)^2))/(1+(B27/fea)^2) -> 0.095185058 | T27: =ATAN(B27*1000*$P$24)-ATAN2(1-$P$24*B27*1000*$P$28*B27*1000,B27*1000*$P$30)-ATAN(B27/fea) -> -1.1829808 | U27: =10*LOG(N27*S27)+Q27+$P$21 -> 52.115504 | V27: =DEGREES(T27+O27)+R27+180 -> 31.587234 | W27: =-U27 -> -52.115504 | Y27: =10*LOG(N27)+20*LOG($C$29) -> 29.046017 | Z27: =DEGREES(O27) -> -80.632957 | AA27: =10*LOG(S27)+Q27+$P$37 -> 23.069487 | AB27: =DEGREES(T27+R27)+180 -> 112.22019
A28: 341.19291 | B28: =A28/1000 -> 0.34119291 | C28: Fm*Ath | D28: =B28*$C$9*1000 -> 0.0010075758 | E28: =B28*1000*$C$18/(1+D28^2) -> 0.040302991 | F28: =D28*E28+$C$24 -> 0.0025406083 | G28: =E28 -> 0.040302991 | H28: =($C$40+($C$34*B28*1000)^2) -> 144.08969 | I28: =ATAN2($C$41,-(B28*1000)) -> -0.02495175 | J28: =$C$48+$C$38*(B28*1000)/TAN($C$50*(B28*1000)) -> 9.7540013 | K28: =$C$51*B28*1000 -> -0.082519454 | L28: =F28*J28-G28*K28+$C$44 -> 0.071287702 | M28: =J28*G28+K28*F28+($C$55+$C$65)*B28*1000 -> 0.39249774 | N28: =H28/(L28^2+M28^2) -> 905.44765 | O28: =I28-ATAN2(L28,M28) -> -1.4160808 | P28: =PS!B81*2*Main!G69*PI()*10^-9 -> 0.00041469023 | Q28: =$P$4+10*LOG((1+($P$6*B28)^2)/(1+($P$8*B28)^2)) -> -23.493182 | R28: =DEGREES(ATAN(B28*$P$6)-ATAN(B28*$P$8)) -> 0 | S28: =((1+($P$24*B28*1000)^2)/((1-$P$28*B28*1000*$P$24*B28*1000)^2+$P$31*(B28*1000)^2))/(1+(B28/fea)^2) -> 0.087407875 | T28: =ATAN(B28*1000*$P$24)-ATAN2(1-$P$24*B28*1000*$P$28*B28*1000,B28*1000*$P$30)-ATAN(B28/fea) -> -1.1929156 | U28: =10*LOG(N28*S28)+Q28+$P$21 -> 51.347885 | V28: =DEGREES(T28+O28)+R28+180 -> 30.515513 | W28: =-U28 -> -51.347885 | Y28: =10*LOG(N28)+20*LOG($C$29) -> 28.64858 | Z28: =DEGREES(O28) -> -81.135456 | AA28: =10*LOG(S28)+Q28+$P$37 -> 22.699305 | AB28: =DEGREES(T28+R28)+180 -> 111.65097
A29: 357.6844 | B29: =A29/1000 -> 0.3576844 | C29: =PS!B71*C27 -> 0.89949203 | D29: =B29*$C$9*1000 -> 0.0010562768 | E29: =B29*1000*$C$18/(1+D29^2) -> 0.042251023 | F29: =D29*E29+$C$24 -> 0.0025446288 | G29: =E29 -> 0.042251023 | H29: =($C$40+($C$34*B29*1000)^2) -> 144.09857 | I29: =ATAN2($C$41,-(B29*1000)) -> -0.02615725 | J29: =$C$48+$C$38*(B29*1000)/TAN($C$50*(B29*1000)) -> 9.7539647 | K29: =$C$51*B29*1000 -> -0.086508015 | L29: =F29*J29-G29*K29+$C$44 -> 0.071656095 | M29: =J29*G29+K29*F29+($C$55+$C$65)*B29*1000 -> 0.4114671 | N29: =H29/(L29^2+M29^2) -> 826.06489 | O29: =I29-ATAN2(L29,M29) -> -1.4245349 | P29: Sum^2 | Q29: =$P$4+10*LOG((1+($P$6*B29)^2)/(1+($P$8*B29)^2)) -> -23.493182 | R29: =DEGREES(ATAN(B29*$P$6)-ATAN(B29*$P$8)) -> 0 | S29: =((1+($P$24*B29*1000)^2)/((1-$P$28*B29*1000*$P$24*B29*1000)^2+$P$31*(B29*1000)^2))/(1+(B29/fea)^2) -> 0.080214227 | T29: =ATAN(B29*1000*$P$24)-ATAN2(1-$P$24*B29*1000*$P$28*B29*1000,B29*1000*$P$30)-ATAN(B29/fea) -> -1.2021598 | U29: =10*LOG(N29*S29)+Q29+$P$21 -> 50.576401 | V29: =DEGREES(T29+O29)+R29+180 -> 29.501481 | W29: =-U29 -> -50.576401 | Y29: =10*LOG(N29)+20*LOG($C$29) -> 28.250088 | Z29: =DEGREES(O29) -> -81.619837 | AA29: =10*LOG(S29)+Q29+$P$37 -> 22.326313 | AB29: =DEGREES(T29+R29)+180 -> 111.12132
A30: 374.973 | B30: =A30/1000 -> 0.374973 | C30: Fmm | D30: =B30*$C$9*1000 -> 0.0011073317 | E30: =B30*1000*$C$18/(1+D30^2) -> 0.044293213 | F30: =D30*E30+$C$24 -> 0.0025490473 | G30: =E30 -> 0.044293213 | H30: =($C$40+($C$34*B30*1000)^2) -> 144.10833 | I30: =ATAN2($C$41,-(B30*1000)) -> -0.027420937 | J30: =$C$48+$C$38*(B30*1000)/TAN($C$50*(B30*1000)) -> 9.7539244 | K30: =$C$51*B30*1000 -> -0.090689362 | L30: =F30*J30-G30*K30+$C$44 -> 0.072060962 | M30: =J30*G30+K30*F30+($C$55+$C$65)*B30*1000 -> 0.43135305 | N30: =H30/(L30^2+M30^2) -> 753.47517 | O30: =I30-ATAN2(L30,M30) -> -1.4326879 | P30: =P24+P26+P28 -> 0.0095161355 | Q30: =$P$4+10*LOG((1+($P$6*B30)^2)/(1+($P$8*B30)^2)) -> -23.493182 | R30: =DEGREES(ATAN(B30*$P$6)-ATAN(B30*$P$8)) -> 0 | S30: =((1+($P$24*B30*1000)^2)/((1-$P$28*B30*1000*$P$24*B30*1000)^2+$P$31*(B30*1000)^2))/(1+(B30/fea)^2) -> 0.073569373 | T30: =ATAN(B30*1000*$P$24)-ATAN2(1-$P$24*B30*1000*$P$28*B30*1000,B30*1000*$P$30)-ATAN(B30/fea) -> -1.2107167 | U30: =10*LOG(N30*S30)+Q30+$P$21 -> 49.801406 | V30: =DEGREES(T30+O30)+R30+180 -> 28.544074 | W30: =-U30 -> -49.801406 | Y30: =10*LOG(N30)+20*LOG($C$29) -> 27.850636 | Z30: =DEGREES(O30) -> -82.086969 | AA30: =10*LOG(S30)+Q30+$P$37 -> 21.95077 | AB30: =DEGREES(T30+R30)+180 -> 110.63104
A31: 393.09724 | B31: =A31/1000 -> 0.39309724 | C31: =PS!B71 -> 4.8572569 | D31: =B31*$C$9*1000 -> 0.0011608543 | E31: =B31*1000*$C$18/(1+D31^2) -> 0.046434111 | F31: =D31*E31+$C$24 -> 0.0025539032 | G31: =E31 -> 0.046434111 | H31: =($C$40+($C$34*B31*1000)^2) -> 144.11905 | I31: =ATAN2($C$41,-(B31*1000)) -> -0.028745609 | J31: =$C$48+$C$38*(B31*1000)/TAN($C$50*(B31*1000)) -> 9.7538802 | K31: =$C$51*B31*1000 -> -0.095072813 | L31: =F31*J31-G31*K31+$C$44 -> 0.072505912 | M31: =J31*G31+K31*F31+($C$55+$C$65)*B31*1000 -> 0.45219983 | N31: =H31/(L31^2+M31^2) -> 687.12606 | O31: =I31-ATAN2(L31,M31) -> -1.4405548 | P31: =P30^2 -> 9.0556834e-05 | Q31: =$P$4+10*LOG((1+($P$6*B31)^2)/(1+($P$8*B31)^2)) -> -23.493182 | R31: =DEGREES(ATAN(B31*$P$6)-ATAN(B31*$P$8)) -> 0 | S31: =((1+($P$24*B31*1000)^2)/((1-$P$28*B31*1000*$P$24*B31*1000)^2+$P$31*(B31*1000)^2))/(1+(B31/fea)^2) -> 0.067439155 | T31: =ATAN(B31*1000*$P$24)-ATAN2(1-$P$24*B31*1000*$P$28*B31*1000,B31*1000*$P$30)-ATAN(B31/fea) -> -1.2185902 | U31: =10*LOG(N31*S31)+Q31+$P$21 -> 49.023231 | V31: =DEGREES(T31+O31)+R31+180 -> 27.642216 | W31: =-U31 -> -49.023231 | Y31: =10*LOG(N31)+20*LOG($C$29) -> 27.450311 | Z31: =DEGREES(O31) -> -82.537708 | AA31: =10*LOG(S31)+Q31+$P$37 -> 21.572921 | AB31: =DEGREES(T31+R31)+180 -> 110.17992
A32: 412.09752 | B32: =A32/1000 -> 0.41209752 | C32: ILPK*L*2*PI() | D32: =B32*$C$9*1000 -> 0.001216964 | E32: =B32*1000*$C$18/(1+D32^2) -> 0.048678487 | F32: =D32*E32+$C$24 -> 0.00255924 | G32: =E32 -> 0.048678487 | H32: =($C$40+($C$34*B32*1000)^2) -> 144.13084 | I32: =ATAN2($C$41,-(B32*1000)) -> -0.0301342 | J32: =$C$48+$C$38*(B32*1000)/TAN($C$50*(B32*1000)) -> 9.7538315 | K32: =$C$51*B32*1000 -> -0.099668138 | L32: =F32*J32-G32*K32+$C$44 -> 0.072994914 | M32: =J32*G32+K32*F32+($C$55+$C$65)*B32*1000 -> 0.47405386 | N32: =H32/(L32^2+M32^2) -> 626.50515 | O32: =I32-ATAN2(L32,M32) -> -1.4481502 | P32: =P33 -> 18.85819 | Q32: =$P$4+10*LOG((1+($P$6*B32)^2)/(1+($P$8*B32)^2)) -> -23.493182 | R32: =DEGREES(ATAN(B32*$P$6)-ATAN(B32*$P$8)) -> 0 | S32: =((1+($P$24*B32*1000)^2)/((1-$P$28*B32*1000*$P$24*B32*1000)^2+$P$31*(B32*1000)^2))/(1+(B32/fea)^2) -> 0.061790267 | T32: =ATAN(B32*1000*$P$24)-ATAN2(1-$P$24*B32*1000*$P$28*B32*1000,B32*1000*$P$30)-ATAN(B32/fea) -> -1.2257846 | U32: =10*LOG(N32*S32)+Q32+$P$21 -> 48.242193 | V32: =DEGREES(T32+O32)+R32+180 -> 26.794818 | W32: =-U32 -> -48.242193 | Y32: =10*LOG(N32)+20*LOG($C$29) -> 27.049193 | Z32: =DEGREES(O32) -> -82.972897 | AA32: =10*LOG(S32)+Q32+$P$37 -> 21.193 | AB32: =DEGREES(T32+R32)+180 -> 109.76772
A33: 432.01617 | B33: =A33/1000 -> 0.43201617 | C33: =C34^2 -> 7.704506e-07 | D33: =B33*$C$9*1000 -> 0.0012757857 | E33: =B33*1000*$C$18/(1+D33^2) -> 0.051031345 | F33: =D33*E33+$C$24 -> 0.0025651051 | G33: =E33 -> 0.051031345 | H33: =($C$40+($C$34*B33*1000)^2) -> 144.1438 | I33: =ATAN2($C$41,-(B33*1000)) -> -0.031589784 | J33: =$C$48+$C$38*(B33*1000)/TAN($C$50*(B33*1000)) -> 9.7537781 | K33: =$C$51*B33*1000 -> -0.10448558 | L33: =F33*J33-G33*K33+$C$44 -> 0.073532329 | M33: =J33*G33+K33*F33+($C$55+$C$65)*B33*1000 -> 0.49696374 | N33: =H33/(L33^2+M33^2) -> 571.13804 | O33: =I33-ATAN2(L33,M33) -> -1.4554888 | P33: =LOOKUP(0,W2:W144,B2:B144) -> 18.85819 | Q33: =$P$4+10*LOG((1+($P$6*B33)^2)/(1+($P$8*B33)^2)) -> -23.493182 | R33: =DEGREES(ATAN(B33*$P$6)-ATAN(B33*$P$8)) -> 0 | S33: =((1+($P$24*B33*1000)^2)/((1-$P$28*B33*1000*$P$24*B33*1000)^2+$P$31*(B33*1000)^2))/(1+(B33/fea)^2) -> 0.056590475 | T33: =ATAN(B33*1000*$P$24)-ATAN2(1-$P$24*B33*1000*$P$28*B33*1000,B33*1000*$P$30)-ATAN(B33/fea) -> -1.2323043 | U33: =10*LOG(N33*S33)+Q33+$P$21 -> 47.45859 | V33: =DEGREES(T33+O33)+R33+180 -> 26.000799 | W33: =-U33 -> -47.45859 | Y33: =10*LOG(N33)+20*LOG($C$29) -> 26.647357 | Z33: =DEGREES(O33) -> -83.393364 | AA33: =10*LOG(S33)+Q33+$P$37 -> 20.811233 | AB33: =DEGREES(T33+R33)+180 -> 109.39416
A34: 452.89758 | B34: =A34/1000 -> 0.45289758 | C34: =C42*PI()*Main!C20*2*10^-6 -> 0.00087775315 | D34: =B34*$C$9*1000 -> 0.0013374505 | E34: =B34*1000*$C$18/(1+D34^2) -> 0.053497925 | F34: =D34*E34+$C$24 -> 0.0025715508 | G34: =E34 -> 0.053497925 | H34: =($C$40+($C$34*B34*1000)^2) -> 144.15803 | I34: =ATAN2($C$41,-(B34*1000)) -> -0.033115579 | J34: =$C$48+$C$38*(B34*1000)/TAN($C$50*(B34*1000)) -> 9.7537193 | K34: =$C$51*B34*1000 -> -0.10953587 | L34: =F34*J34-G34*K34+$C$44 -> 0.074122951 | M34: =J34*G34+K34*F34+($C$55+$C$65)*B34*1000 -> 0.52098044 | N34: =H34/(L34^2+M34^2) -> 520.58616 | O34: =I34-ATAN2(L34,M34) -> -1.4625845 | P34: =LOOKUP(0,W2:W144,V2:V144) -> 43.862126 | Q34: =$P$4+10*LOG((1+($P$6*B34)^2)/(1+($P$8*B34)^2)) -> -23.493182 | R34: =DEGREES(ATAN(B34*$P$6)-ATAN(B34*$P$8)) -> 0 | S34: =((1+($P$24*B34*1000)^2)/((1-$P$28*B34*1000*$P$24*B34*1000)^2+$P$31*(B34*1000)^2))/(1+(B34/fea)^2) -> 0.051808777 | T34: =ATAN(B34*1000*$P$24)-ATAN2(1-$P$24*B34*1000*$P$28*B34*1000,B34*1000*$P$30)-ATAN(B34/fea) -> -1.2381539 | U34: =10*LOG(N34*S34)+Q34+$P$21 -> 46.672705 | V34: =DEGREES(T34+O34)+R34+180 -> 25.259087 | W34: =-U34 -> -46.672705 | Y34: =10*LOG(N34)+20*LOG($C$29) -> 26.244873 | Z34: =DEGREES(O34) -> -83.799921 | AA34: =10*LOG(S34)+Q34+$P$37 -> 20.427833 | AB34: =DEGREES(T34+R34)+180 -> 109.05901
A35: 474.78829 | B35: =A35/1000 -> 0.47478829 | C35: 1-D | D35: =B35*$C$9*1000 -> 0.0014020959 | E35: =B35*1000*$C$18/(1+D35^2) -> 0.056083727 | F35: =D35*E35+$C$24 -> 0.0025786348 | G35: =E35 -> 0.056083727 | H35: =($C$40+($C$34*B35*1000)^2) -> 144.17368 | I35: =ATAN2($C$41,-(B35*1000)) -> -0.034714958 | J35: =$C$48+$C$38*(B35*1000)/TAN($C$50*(B35*1000)) -> 9.7536547 | K35: =$C$51*B35*1000 -> -0.11483026 | L35: =F35*J35-G35*K35+$C$44 -> 0.074772046 | M35: =J35*G35+K35*F35+($C$55+$C$65)*B35*1000 -> 0.54615739 | N35: =H35/(L35^2+M35^2) -> 474.44474 | O35: =I35-ATAN2(L35,M35) -> -1.4694515 | Q35: =$P$4+10*LOG((1+($P$6*B35)^2)/(1+($P$8*B35)^2)) -> -23.493182 | R35: =DEGREES(ATAN(B35*$P$6)-ATAN(B35*$P$8)) -> 0 | S35: =((1+($P$24*B35*1000)^2)/((1-$P$28*B35*1000*$P$24*B35*1000)^2+$P$31*(B35*1000)^2))/(1+(B35/fea)^2) -> 0.047415533 | T35: =ATAN(B35*1000*$P$24)-ATAN2(1-$P$24*B35*1000*$P$28*B35*1000,B35*1000*$P$30)-ATAN(B35/fea) -> -1.2433377 | U35: =10*LOG(N35*S35)+Q35+$P$21 -> 45.884808 | V35: =DEGREES(T35+O35)+R35+180 -> 24.568631 | W35: =-U35 -> -45.884808 | Y35: =10*LOG(N35)+20*LOG($C$29) -> 25.841803 | Z35: =DEGREES(O35) -> -84.193367 | AA35: =10*LOG(S35)+Q35+$P$37 -> 20.043006 | AB35: =DEGREES(T35+R35)+180 -> 108.762
A36: 497.73708 | B36: =A36/1000 -> 0.49773708 | C36: =1-PS!B67 -> 0.059886216 | D36: =B36*$C$9*1000 -> 0.0014698659 | E36: =B36*1000*$C$18/(1+D36^2) -> 0.058794511 | F36: =D36*E36+$C$24 -> 0.00258642 | G36: =E36 -> 0.058794511 | H36: =($C$40+($C$34*B36*1000)^2) -> 144.19087 | I36: =ATAN2($C$41,-(B36*1000)) -> -0.036391451 | J36: =$C$48+$C$38*(B36*1000)/TAN($C$50*(B36*1000)) -> 9.7535838 | K36: =$C$51*B36*1000 -> -0.12038056 | L36: =F36*J36-G36*K36+$C$44 -> 0.075485405 | M36: =J36*G36+K36*F36+($C$55+$C$65)*B36*1000 -> 0.57255058 | N36: =H36/(L36^2+M36^2) -> 432.34061 | O36: =I36-ATAN2(L36,M36) -> -1.4761032 | P36: gm*Roth | Q36: =$P$4+10*LOG((1+($P$6*B36)^2)/(1+($P$8*B36)^2)) -> -23.493182 | R36: =DEGREES(ATAN(B36*$P$6)-ATAN(B36*$P$8)) -> 0 | S36: =((1+($P$24*B36*1000)^2)/((1-$P$28*B36*1000*$P$24*B36*1000)^2+$P$31*(B36*1000)^2))/(1+(B36/fea)^2) -> 0.043382538 | T36: =ATAN(B36*1000*$P$24)-ATAN2(1-$P$24*B36*1000*$P$28*B36*1000,B36*1000*$P$30)-ATAN(B36/fea) -> -1.2478599 | U36: =10*LOG(N36*S36)+Q36+$P$21 -> 45.095156 | V36: =DEGREES(T36+O36)+R36+180 -> 23.928408 | W36: =-U36 -> -45.095156 | Y36: =10*LOG(N36)+20*LOG($C$29) -> 25.438207 | Z36: =DEGREES(O36) -> -84.574484 | AA36: =10*LOG(S36)+Q36+$P$37 -> 19.656949 | AB36: =DEGREES(T36+R36)+180 -> 108.50289
A37: 521.7951 | B37: =A37/1000 -> 0.5217951 | C37: Fmm*Ri*VoF*PI()/fs | D37: =B37*$C$9*1000 -> 0.0015409116 | E37: =B37*1000*$C$18/(1+D37^2) -> 0.061636318 | F37: =D37*E37+$C$24 -> 0.0025949761 | G37: =E37 -> 0.061636318 | H37: =($C$40+($C$34*B37*1000)^2) -> 144.20977 | I37: =ATAN2($C$41,-(B37*1000)) -> -0.038148758 | J37: =$C$48+$C$38*(B37*1000)/TAN($C$50*(B37*1000)) -> 9.7535058 | K37: =$C$51*B37*1000 -> -0.12619913 | L37: =F37*J37-G37*K37+$C$44 -> 0.076269388 | M37: =J37*G37+K37*F37+($C$55+$C$65)*B37*1000 -> 0.60021868 | N37: =H37/(L37^2+M37^2) -> 393.93022 | O37: =I37-ATAN2(L37,M37) -> -1.4825531 | P37: =20*LOG(PS!B76*PS!B81*1000) -> 56.776982 | Q37: =$P$4+10*LOG((1+($P$6*B37)^2)/(1+($P$8*B37)^2)) -> -23.493182 | R37: =DEGREES(ATAN(B37*$P$6)-ATAN(B37*$P$8)) -> 0 | S37: =((1+($P$24*B37*1000)^2)/((1-$P$28*B37*1000*$P$24*B37*1000)^2+$P$31*(B37*1000)^2))/(1+(B37/fea)^2) -> 0.039683074 | T37: =ATAN(B37*1000*$P$24)-ATAN2(1-$P$24*B37*1000*$P$28*B37*1000,B37*1000*$P$30)-ATAN(B37/fea) -> -1.2517246 | U37: =10*LOG(N37*S37)+Q37+$P$21 -> 44.303992 | V37: =DEGREES(T37+O37)+R37+180 -> 23.337425 | W37: =-U37 -> -44.303992 | Y37: =10*LOG(N37)+20*LOG($C$29) -> 25.034139 | Z37: =DEGREES(O37) -> -84.944036 | AA37: =10*LOG(S37)+Q37+$P$37 -> 19.269852 | AB37: =DEGREES(T37+R37)+180 -> 108.28146
A38: 547.01596 | B38: =A38/1000 -> 0.54701596 | C38: =C31*PS!B66*PS!B6*10^-3*C50 -> 0.00030468756 | D38: =B38*$C$9*1000 -> 0.0016153913 | E38: =B38*1000*$C$18/(1+D38^2) -> 0.064615481 | F38: =D38*E38+$C$24 -> 0.0026043793 | G38: =E38 -> 0.064615481 | H38: =($C$40+($C$34*B38*1000)^2) -> 144.23054 | I38: =ATAN2($C$41,-(B38*1000)) -> -0.03999075 | J38: =$C$48+$C$38*(B38*1000)/TAN($C$50*(B38*1000)) -> 9.7534201 | K38: =$C$51*B38*1000 -> -0.13229893 | L38: =F38*J38-G38*K38+$C$44 -> 0.077130989 | M38: =J38*G38+K38*F38+($C$55+$C$65)*B38*1000 -> 0.62922319 | N38: =H38/(L38^2+M38^2) -> 358.89759 | O38: =I38-ATAN2(L38,M38) -> -1.4888143 | Q38: =$P$4+10*LOG((1+($P$6*B38)^2)/(1+($P$8*B38)^2)) -> -23.493182 | R38: =DEGREES(ATAN(B38*$P$6)-ATAN(B38*$P$8)) -> 0 | S38: =((1+($P$24*B38*1000)^2)/((1-$P$28*B38*1000*$P$24*B38*1000)^2+$P$31*(B38*1000)^2))/(1+(B38/fea)^2) -> 0.036291931 | T38: =ATAN(B38*1000*$P$24)-ATAN2(1-$P$24*B38*1000*$P$28*B38*1000,B38*1000*$P$30)-ATAN(B38/fea) -> -1.2549353 | U38: =10*LOG(N38*S38)+Q38+$P$21 -> 43.511552 | V38: =DEGREES(T38+O38)+R38+180 -> 22.794726 | W38: =-U38 -> -43.511552 | Y38: =10*LOG(N38)+20*LOG($C$29) -> 24.629652 | Z38: =DEGREES(O38) -> -85.302775 | AA38: =10*LOG(S38)+Q38+$P$37 -> 18.8819 | AB38: =DEGREES(T38+R38)+180 -> 108.0975
